Workbook

Sheet BOM
A1: Category | B1: Item | C1: Spec/notes | D1: Used for | E1: Qty needed | F1: Have it | G1: Qty to buy | H1: Unit price CAD | I1: Line total | J1: Store | K1: Link | L1: Search link | M1: Price checked date | N1: Price status | O1: Cart #
A2: Computer & displays (owned) | B2: Gaming PC (Ryzen 9 5900X, RX 6800 XT 16 GB, 32 GB RAM) | C2: Linux Mint; RX 6800 XT: 2x DP 1.4, 1x HDMI 2.1, 1x USB-C, max 4 displays | D2: Runs the Godot game (3 windows) | E2: 1 | F2: =TRUE() -> TRUE | G2: =IF(OR(F2=TRUE(),F2="TRUE"),0,E2) -> 0 | H2: 0 | I2: =IF(H2="","",G2*H2) -> 0 | J2: Owned | N2: Owned | O2: =IF(AND(J2="Amazon.ca",G2>0,ISERROR(SEARCH("ALTERNATIVE",A2))),MAX(O$1:O1)+1,"")
A3: Computer & displays (owned) | B3: Sceptre C275B-144R 27" curved monitor | C3: 1920x1080 144 Hz, 1800R, VESA 100 M4, HDMI/DP/DVI, 3.80 kg | D3: PILOT window (left kid), in the pod | E3: 1 | F3: =TRUE() -> TRUE | G3: =IF(OR(F3=TRUE(),F3="TRUE"),0,E3) -> 0 | H3: 0 | I3: =IF(H3="","",G3*H3) -> 0 | J3: Owned | N3: Owned | O3: =IF(AND(J3="Amazon.ca",G3>0,ISERROR(SEARCH("ALTERNATIVE",A3))),MAX(O$1:O2)+1,"")
A4: Computer & displays (owned) | B4: Sceptre C275W-1920RN 27" curved monitor | C4: 1920x1080 75 Hz, 1800R, VESA 75 M4, HDMI + VGA only, 3.40 kg | D4: OPS window (right kid), in the pod | E4: 1 | F4: =TRUE() -> TRUE | G4: =IF(OR(F4=TRUE(),F4="TRUE"),0,E4) -> 0 | H4: 0 | I4: =IF(H4="","",G4*H4) -> 0 | J4: Owned | N4: Owned | O4: =IF(AND(J4="Amazon.ca",G4>0,ISERROR(SEARCH("ALTERNATIVE",A4))),MAX(O$1:O3)+1,"")
A5: Computer & displays (owned) | B5: ViewSonic TD2220 22" touchscreen | C5: 21.5" 1920x1080, optical 2-point touch over USB-B, VGA + DVI-D only, VESA 100 | D5: Centre console touchscreen (in the cradle) | E5: 1 | F5: =TRUE() -> TRUE | G5: =IF(OR(F5=TRUE(),F5="TRUE"),0,E5) -> 0 | H5: 0 | I5: =IF(H5="","",G5*H5) -> 0 | J5: Owned | N5: Owned | O5: =IF(AND(J5="Amazon.ca",G5>0,ISERROR(SEARCH("ALTERNATIVE",A5))),MAX(O$1:O4)+1,"")
A6: Computer & displays (owned) | B6: HY300 mini projectors | C6: Only in the projector-dome feasibility study (docs/mechanical/projector_dome_study.md); not in the core build | D6: Optional dome / ambient projection | E6: 3 | F6: =TRUE() -> TRUE | G6: =IF(OR(F6=TRUE(),F6="TRUE"),0,E6) -> 0 | H6: 0 | I6: =IF(H6="","",G6*H6) -> 0 | J6: Owned | N6: Owned | O6: =IF(AND(J6="Amazon.ca",G6>0,ISERROR(SEARCH("ALTERNATIVE",A6))),MAX(O$1:O5)+1,"")
A7: Computer & displays (owned) | B7: 3-axis joysticks with top button (X, Y, twist pots + button) | C7: "A couple" owned; assumed potentiometer sticks (see electronics README). Mounting pattern still to measure | D7: PILOT and OPS sticks | E7: 2 | F7: =TRUE() -> TRUE | G7: =IF(OR(F7=TRUE(),F7="TRUE"),0,E7) -> 0 | H7: 0 | I7: =IF(H7="","",G7*H7) -> 0 | J7: Owned | N7: Owned | O7: =IF(AND(J7="Amazon.ca",G7>0,ISERROR(SEARCH("ALTERNATIVE",A7))),MAX(O$1:O6)+1,"")
A8: Video & USB cabling | B8: DisplayPort 1.4 cable, 3 m (10 ft), VESA certified | C8: Latching connectors; 3-5 m per displays.md - measure from the PC location | Listing: "Silkland VESA Certified DisplayPort Cable, Long DP Cable 10FT, Braided" | D8: GPU DP1 -> C275B-144R (1080p 144 Hz) | E8: 1 | F8: =FALSE() -> FALSE | G8: =IF(OR(F8=TRUE(),F8="TRUE"),0,E8) -> 1 | H8: 16.99 | I8: =IF(H8="","",G8*H8) -> 16.99 | J8: Amazon.ca | K8: https://www.amazon.ca/dp/B0BRPZHK36 | L8: https://www.amazon.ca/s?k=displayport+1.4+cable+10+ft | M8: 2026-10-08 | N8: Verified amazon.ca price | O8: =IF(AND(J8="Amazon.ca",G8>0,ISERROR(SEARCH("ALTERNATIVE",A8))),MAX(O$1:O7)+1,"") -> 1
A9: Video & USB cabling | B9: HDMI cable, 3 m (10 ft) | C9: High speed; C275W only has HDMI/VGA | Listing: "Amazon Basics High-Speed 4K HDMI Cable - 10 Feet" | D9: GPU HDMI -> C275W-1920RN (1080p 75 Hz) | E9: 1 | F9: =FALSE() -> FALSE | G9: =IF(OR(F9=TRUE(),F9="TRUE"),0,E9) -> 1 | H9: 10.76 | I9: =IF(H9="","",G9*H9) -> 10.76 | J9: Amazon.ca | K9: https://www.amazon.ca/dp/B014I8T0YQ | L9: https://www.amazon.ca/s?k=hdmi+cable+10+ft | M9: 2026-10-08 | N9: Verified amazon.ca price | O9: =IF(AND(J9="Amazon.ca",G9>0,ISERROR(SEARCH("ALTERNATIVE",A9))),MAX(O$1:O8)+1,"") -> 2
A10: Video & USB cabling | B10: DisplayPort -> DVI-D adapter cable, passive, 3 m (10 ft) | C10: Single-link DVI-D, 1080p60, passive DP++ is fine. One-piece cable = no separate DVI cable needed. Alternative if you already have the TD2220 DVI cable: StarTech DP2DVI2 passive adapter https://www.amazon.ca/dp/B0035PS57C | Listing: "BENFEI DisplayPort to DVI 10 Feet Cable, Uni-Directional" | D10: GPU DP2 -> TD2220 DVI-D in | E10: 1 | F10: =FALSE() -> FALSE | G10: =IF(OR(F10=TRUE(),F10="TRUE"),0,E10) -> 1 | H10: 16.99 | I10: =IF(H10="","",G10*H10) -> 16.99 | J10: Amazon.ca | K10: https://www.amazon.ca/dp/B06WD33P34 | L10: https://www.amazon.ca/s?k=displayport+to+dvi-d+cable+10+ft | M10: 2026-10-08 | N10: Verified amazon.ca price | O10: =IF(AND(J10="Amazon.ca",G10>0,ISERROR(SEARCH("ALTERNATIVE",A10))),MAX(O$1:O9)+1,"") -> 3
A11: Video & USB cabling | B11: USB-A to USB-B cable, 3 m (10 ft) | C11: USB 2.0; <= 5 m (or use an active extension) | Listing: "AINOPE USB Printer Cable 10FT, Nylon Braided USB A to USB B MIDI Cable" | D11: PC -> TD2220 touch (HID) | E11: 1 | F11: =FALSE() -> FALSE | G11: =IF(OR(F11=TRUE(),F11="TRUE"),0,E11) -> 1 | H11: 12.99 | I11: =IF(H11="","",G11*H11) -> 12.99 | J11: Amazon.ca | K11: https://www.amazon.ca/dp/B07ZRBRDHG | L11: https://www.amazon.ca/s?k=usb+a+to+usb+b+cable+10+ft | M11: 2026-10-08 | N11: Verified amazon.ca price | O11: =IF(AND(J11="Amazon.ca",G11>0,ISERROR(SEARCH("ALTERNATIVE",A11))),MAX(O$1:O10)+1,"") -> 4
A12: Video & USB cabling | B12: USB-A to USB-C data cables 1.8 m (6 ft), 3-pack | C12: Must be DATA cables; plug into each board's "USB" port (not "UART") | Listing: "Cable Matters 3-Pack USB A to USB C Cable, 6ft, Black" | D12: 3x ESP32-S3 boards -> PC / hub | E12: 1 | F12: =FALSE() -> FALSE | G12: =IF(OR(F12=TRUE(),F12="TRUE"),0,E12) -> 1 | H12: 9.99 | I12: =IF(H12="","",G12*H12) -> 9.99 | J12: Amazon.ca | K12: https://www.amazon.ca/dp/B0CLZ9J2F5 | L12: https://www.amazon.ca/s?k=usb+a+to+usb+c+data+cable+6+ft+3+pack | M12: 2026-10-08 | N12: Verified amazon.ca price | O12: =IF(AND(J12="Amazon.ca",G12>0,ISERROR(SEARCH("ALTERNATIVE",A12))),MAX(O$1:O11)+1,"") -> 5
A13: Video & USB cabling | B13: Powered USB 3.0 hub, 7-port, with power adapter | C13: Electronics README: a powered USB 3 hub is fine | Listing: "TP-Link UH720, Powered USB 3.0 Hub, 7 Data + 2 Charging Ports" | D13: 3x ESP32-S3 + TD2220 touch | E13: 1 | F13: =FALSE() -> FALSE | G13: =IF(OR(F13=TRUE(),F13="TRUE"),0,E13) -> 1 | H13: 39.99 | I13: =IF(H13="","",G13*H13) -> 39.99 | J13: Amazon.ca | K13: https://www.amazon.ca/dp/B00SCX6I8A | L13: https://www.amazon.ca/s?k=powered+usb+3.0+hub+7+port | M13: 2026-10-08 | N13: Verified amazon.ca price | O13: =IF(AND(J13="Amazon.ca",G13>0,ISERROR(SEARCH("ALTERNATIVE",A13))),MAX(O$1:O12)+1,"") -> 6
A14: Video & USB cabling | B14: Expandable braided sleeve 25 mm (1"), 7.6 m (25 ft) | C14: BOM: 5 m of 25-30 mm sleeve | Listing: "25ft - 1 inch PET Expandable Braided Sleeving – Black – Alex Tech Braided Cable Sleeve" | D14: 200 mm U service loops at the pod + cradle pivots | E14: 1 | F14: =FALSE() -> FALSE | G14: =IF(OR(F14=TRUE(),F14="TRUE"),0,E14) -> 1 | H14: 15.98 | I14: =IF(H14="","",G14*H14) -> 15.98 | J14: Amazon.ca | K14: https://www.amazon.ca/dp/B073YLYBJF | L14: https://www.amazon.ca/s?k=braided+cable+sleeve+1+inch+25+ft | M14: 2026-10-08 | N14: Verified amazon.ca price | O14: =IF(AND(J14="Amazon.ca",G14>0,ISERROR(SEARCH("ALTERNATIVE",A14))),MAX(O$1:O13)+1,"") -> 7
A15: Controllers & logic | B15: ESP32-S3-DevKitC-1-N8R8, 5-pack | C15: Must be the S3 DevKitC-1 with both "USB" + "UART" ports. 3 needed + 2 spares | Listing: "5pcs ESP32 S3 Development Board ESP32-S3-DevKitC-1-N8R8 MCU Module" | D15: Falcon Pilot / Ops / Command | E15: 1 | F15: =FALSE() -> FALSE | G15: =IF(OR(F15=TRUE(),F15="TRUE"),0,E15) -> 1 | H15: 71.98 | I15: =IF(H15="","",G15*H15) -> 71.98 | J15: Amazon.ca | K15: https://www.amazon.ca/dp/B0D93FLZLH | L15: https://www.amazon.ca/s?k=ESP32-S3-DevKitC-1+N8R8 | M15: 2026-10-08 | N15: Verified amazon.ca price | O15: =IF(AND(J15="Amazon.ca",G15>0,ISERROR(SEARCH("ALTERNATIVE",A15))),MAX(O$1:O14)+1,"") -> 8
A16: Controllers & logic | B16: 74HC165 shift register DIP-16, 25 pcs | C16: 10 needed (3 Pilot, 3 Ops, 4 Command) + 2 spares | Listing: "SING F LTD 25Pcs DIP16 IC 8BIT Parallel-in/Serial-Out Shift Register 16 Pin Computer Through Hole De" | D16: Switch inputs | E16: 1 | F16: =FALSE() -> FALSE | G16: =IF(OR(F16=TRUE(),F16="TRUE"),0,E16) -> 1 | H16: 18.49 | I16: =IF(H16="","",G16*H16) -> 18.49 | J16: Amazon.ca | K16: https://www.amazon.ca/dp/B0D2THXFQ6 | L16: https://www.amazon.ca/s?k=SN74HC165N+DIP-16 | M16: 2026-10-08 | N16: Verified amazon.ca price | O16: =IF(AND(J16="Amazon.ca",G16>0,ISERROR(SEARCH("ALTERNATIVE",A16))),MAX(O$1:O15)+1,"") -> 9
A17: Controllers & logic | B17: DIP IC socket assortment (incl. 14- and 16-pin) | C17: 12x DIP-16 for the 74HC165s + 1x DIP-14 for the 74AHCT125 | Listing: "Glarks 122Pcs 2.54mm Pitch DIP IC Sockets Solder Type Adaptor Assortment Kit (6 / 8 / 14 / 16 / 18 /" | D17: Socketed chips on the perfboards | E17: 1 | F17: =FALSE() -> FALSE | G17: =IF(OR(F17=TRUE(),F17="TRUE"),0,E17) -> 1 | H17: 16.99 | I17: =IF(H17="","",G17*H17) -> 16.99 | J17: Amazon.ca | K17: https://www.amazon.ca/dp/B01GOLSUAU | L17: https://www.amazon.ca/s?k=dip+ic+socket+assortment | M17: 2026-10-08 | N17: Verified amazon.ca price | O17: =IF(AND(J17="Amazon.ca",G17>0,ISERROR(SEARCH("ALTERNATIVE",A17))),MAX(O$1:O16)+1,"") -> 10
A18: Controllers & logic | B18: 10 kOhm bussed resistor network SIP-9 (A103J), 20 pcs | C18: 12 needed (one per 74HC165, 8 pull-ups) | Listing: "20pcs A103J 9pin 10K ohm DIP Exclusion 9 PINS Network Resistor Array" | D18: 74HC165 input pull-ups | E18: 1 | F18: =FALSE() -> FALSE | G18: =IF(OR(F18=TRUE(),F18="TRUE"),0,E18) -> 1 | H18: 8.88 | I18: =IF(H18="","",G18*H18) -> 8.88 | J18: Amazon.ca | K18: https://www.amazon.ca/dp/B0D4BXJ1SX | L18: https://www.amazon.ca/s?k=10k+bussed+resistor+network+sip+9+A103J | M18: 2026-10-08 | N18: Verified amazon.ca price | O18: =IF(AND(J18="Amazon.ca",G18>0,ISERROR(SEARCH("ALTERNATIVE",A18))),MAX(O$1:O17)+1,"") -> 11
A19: Controllers & logic | B19: 100 nF ceramic capacitors, 100 pcs | C19: 52 needed: 20 at chips/boards + 32 at the WS2812D-F5 LEDs | Listing: "50V Ceramic Capacitor,50V 100NF(104 100pcs" | D19: Decoupling | E19: 1 | F19: =FALSE() -> FALSE | G19: =IF(OR(F19=TRUE(),F19="TRUE"),0,E19) -> 1 | H19: 6.55 | I19: =IF(H19="","",G19*H19) -> 6.55 | J19: Amazon.ca | K19: https://www.amazon.ca/dp/B09JWTW1GT | L19: https://www.amazon.ca/s?k=100nf+ceramic+capacitor+104+100pcs | M19: 2026-10-08 | N19: Verified amazon.ca price | O19: =IF(AND(J19="Amazon.ca",G19>0,ISERROR(SEARCH("ALTERNATIVE",A19))),MAX(O$1:O18)+1,"") -> 12
... A40: LED backlighting | B40: WS2812B LED strip 5 V, 60 LED/m, 5 m, IP30 (no sleeve) | C40: BTF-LIGHTING ECO; this ASIN is the Black PCB / IP30 / 5 m 60 LED/m variant (checked). 10 mm wide strip fits the 12 mm channels; ~136 label LEDs + panel hops | Listing: "BTF-LIGHTING WS2812B IC ECO Individually Addressable RGB LED Strip Lights" | D40: Backlit labels, one continuous strip | E40: 1 | F40: =FALSE() -> FALSE | G40: =IF(OR(F40=TRUE(),F40="TRUE"),0,E40) -> 1 | H40: 25.99 | I40: =IF(H40="","",G40*H40) -> 25.99 | J40: Amazon.ca | K40: https://www.amazon.ca/dp/B0F8VDHK22 | L40: https://www.amazon.ca/s?k=ws2812b+5m+60+led+ip30 | M40: 2026-10-08 | N40: Verified amazon.ca price | O40: =IF(AND(J40="Amazon.ca",G40>0,ISERROR(SEARCH("ALTERNATIVE",A40))),MAX(O$1:O39)+1,"") -> 33
A41: LED backlighting | B41: WS2812D-F5 5 mm through-hole addressable RGB LEDs, ~40 pcs | C41: 32 status holes + spares; spliced into the same data line. NOT found on amazon.ca (only plain 4-pin RGB). Try AliExpress / Digi-Key, or use plain LEDs + 74HC595 (firmware change) | D41: Status/indicator LEDs (*_LED ids) | E41: 1 | F41: =FALSE() -> FALSE | G41: =IF(OR(F41=TRUE(),F41="TRUE"),0,E41) -> 1 | H41: 20 | I41: =IF(H41="","",G41*H41) -> 20 | J41: Amazon.ca | L41: https://www.amazon.ca/s?k=WS2812D-F5+5mm+addressable+RGB+LED | N41: No suitable listing found - estimate | O41: =IF(AND(J41="Amazon.ca",G41>0,ISERROR(SEARCH("ALTERNATIVE",A41))),MAX(O$1:O40)+1,"") -> 34
A42: LED backlighting | B42: 5 mm LED holders / bezels, 50 pcs | C42: 32 needed. Note: you may already own some of these (tick Have it if so). | Listing: "PATIKIL 5mm Emitting Diode Holder, 50 Pcs Plastic Flat LED Holder Clip Mounting Bracket Socket Cap f" | D42: Status LED holes | E42: 1 | F42: =FALSE() -> FALSE | G42: =IF(OR(F42=TRUE(),F42="TRUE"),0,E42) -> 1 | H42: 9.19 | I42: =IF(H42="","",G42*H42) -> 9.19 | J42: Amazon.ca | K42: https://www.amazon.ca/dp/B0DJR583BY | L42: https://www.amazon.ca/s?k=5mm+led+holder+bezel | M42: 2026-10-08 | N42: Verified amazon.ca price | O42: =IF(AND(J42="Amazon.ca",G42>0,ISERROR(SEARCH("ALTERNATIVE",A42))),MAX(O$1:O41)+1,"") -> 35
A43: LED backlighting | B43: Mean Well LRS-50-5 (5 V 10 A) power supply | C43: Firmware caps strip at 8 A; inject power at start/middle/end | Listing: "Mean Well LRS-50-5 Switching Power Supply, Single Output, 5V, 10A, 50W, 3.9" L x 3.23" W x 1.18" H" | D43: LED strip power | E43: 1 | F43: =FALSE() -> FALSE | G43: =IF(OR(F43=TRUE(),F43="TRUE"),0,E43) -> 1 | H43: 31.75 | I43: =IF(H43="","",G43*H43) -> 31.75 | J43: Amazon.ca | K43: https://www.amazon.ca/dp/B019GYOCMM | L43: https://www.amazon.ca/s?k=mean+well+lrs-50-5 | M43: 2026-10-08 | N43: Verified amazon.ca price | O43: =IF(AND(J43="Amazon.ca",G43>0,ISERROR(SEARCH("ALTERNATIVE",A43))),MAX(O$1:O42)+1,"") -> 36
A44: LED backlighting | B44: Inline 5x20 mm fuse holders + fast-blow fuse kit | C44: Use a 10 A fuse at the PSU output | Listing: "Fuse Kit Car Fuses - 10pcs 5x20mm AGC Inline Fuse Holder + 100pcs 5x20mm Fast-Blow Glass Fuses Quick" | D44: LED PSU output fuse | E44: 1 | F44: =FALSE() -> FALSE | G44: =IF(OR(F44=TRUE(),F44="TRUE"),0,E44) -> 1 | H44: 14.99 | I44: =IF(H44="","",G44*H44) -> 14.99 | J44: Amazon.ca | K44: https://www.amazon.ca/dp/B07X8WL5TC | L44: https://www.amazon.ca/s?k=inline+fuse+holder+5x20+kit | M44: 2026-10-08 | N44: Verified amazon.ca price | O44: =IF(AND(J44="Amazon.ca",G44>0,ISERROR(SEARCH("ALTERNATIVE",A44))),MAX(O$1:O43)+1,"") -> 37
A45: LED backlighting | B45: 16 AWG red/black 2-conductor wire, 15 m (50 ft) | C45: LED power trunk. Prefer pure copper (check listing) | Listing: "VIABRICO 16AWG 50FT Electrical Wire Cable 2 Conductors Red Black Cable Hookup LED Lighting Strips Fl" | D45: LED 5 V trunk | E45: 1 | F45: =FALSE() -> FALSE | G45: =IF(OR(F45=TRUE(),F45="TRUE"),0,E45) -> 1 | H45: 16.99 | I45: =IF(H45="","",G45*H45) -> 16.99 | J45: Amazon.ca | K45: https://www.amazon.ca/dp/B0CNRTZ4N3 | L45: https://www.amazon.ca/s?k=16+awg+red+black+wire+copper | M45: 2026-10-08 | N45: Verified amazon.ca price | O45: =IF(AND(J45="Amazon.ca",G45>0,ISERROR(SEARCH("ALTERNATIVE",A45))),MAX(O$1:O44)+1,"") -> 38
A46: LED backlighting | B46: 18 AWG red/black silicone wire, 7.6 m (25 ft) | C46: Injection drops; 2nd roll for the 12 V switch circuits of the interlock | Listing: "BNTECHGO 18 AWG Silicone Wire Red Black 25ft Stranded Tinned Copper Wire" | D46: LED injection + interlock switch wiring | E46: 2 | F46: =FALSE() -> FALSE | G46: =IF(OR(F46=TRUE(),F46="TRUE"),0,E46) -> 2 | H46: 19.82 | I46: =IF(H46="","",G46*H46) -> 39.64 | J46: Amazon.ca | K46: https://www.amazon.ca/dp/B07HGTKQ89 | L46: https://www.amazon.ca/s?k=18+awg+red+black+silicone+wire | M46: 2026-10-08 | N46: Verified amazon.ca price | O46: =IF(AND(J46="Amazon.ca",G46>0,ISERROR(SEARCH("ALTERNATIVE",A46))),MAX(O$1:O45)+1,"") -> 39
A47: LED backlighting | B47: JST-SM 3-pin pigtails (WS2812), 60 pcs | C47: Panel-to-panel strip hops, removable panels | Listing: "JST SM 3 Pin Connectors for WS2812B WS2812 WS2811, 22AWG LED Male/Female Connector Adapter Open Wire" | D47: LED strip connectors | E47: 1 | F47: =FALSE() -> FALSE | G47: =IF(OR(F47=TRUE(),F47="TRUE"),0,E47) -> 1 | H47: 18.59 | I47: =IF(H47="","",G47*H47) -> 18.59 | J47: Amazon.ca | K47: https://www.amazon.ca/dp/B0CP94DL4F | L47: https://www.amazon.ca/s?k=jst+sm+3+pin+connector+ws2812 | M47: 2026-10-08 | N47: Verified amazon.ca price | O47: =IF(AND(J47="Amazon.ca",G47>0,ISERROR(SEARCH("ALTERNATIVE",A47))),MAX(O$1:O46)+1,"") -> 40
A48: Printed parts: filament & inserts | B48: PETG filament 1.75 mm BLACK, 1 kg | C48: Estimate 5.3 kg incl. 15 % waste (see Notes sheet) -> 6 spools. Panels, enclosures, mounts, harness hub (PETG required there) | Listing: "ELEGOO PETG 3D Printer Filament 1.75mm Black 1KG, Strong & Durable" | D48: All black printed parts | E48: 6 | F48: =FALSE() -> FALSE | G48: =IF(OR(F48=TRUE(),F48="TRUE"),0,E48) -> 6 | H48: 19.94 | I48: =IF(H48="","",G48*H48) -> 119.64 | J48: Amazon.ca | K48: https://www.amazon.ca/dp/B0D41Y3WWZ | L48: https://www.amazon.ca/s?k=petg+filament+1.75+black+1kg | M48: 2026-10-08 | N48: Verified amazon.ca price | O48: =IF(AND(J48="Amazon.ca",G48>0,ISERROR(SEARCH("ALTERNATIVE",A48))),MAX(O$1:O47)+1,"") -> 41
A49: Printed parts: filament & inserts | B49: PETG filament 1.75 mm WHITE, 1 kg | C49: Estimate only ~0.06 kg (letters/inserts) - 1 spool is plenty | Listing: "ELEGOO Rapid PETG 3D Printer Filament 1.75mm White 1KG" | D49: Backlit letters / letter inserts | E49: 1 | F49: =FALSE() -> FALSE | G49: =IF(OR(F49=TRUE(),F49="TRUE"),0,E49) -> 1 | H49: 20.89 | I49: =IF(H49="","",G49*H49) -> 20.89 | J49: Amazon.ca | K49: https://www.amazon.ca/dp/B0CMC78XKT | L49: https://www.amazon.ca/s?k=petg+filament+1.75+white+1kg | M49: 2026-10-08 | N49: Verified amazon.ca price | O49: =IF(AND(J49="Amazon.ca",G49>0,ISERROR(SEARCH("ALTERNATIVE",A49))),MAX(O$1:O48)+1,"") -> 42
A50: Printed parts: filament & inserts | B50: Brass heat-set inserts kit M2-M6 (360 pcs) | C50: Harness hub 5x M3 each; pivot cable clamps M4 | Listing: "Besitu 360Pcs Threaded Inserts M2 M2.5 M3 M4 M5 M6 Brass Heat Set Insert for Plastic Metric Knurled " | D50: Harness hub, pivot cable clamps | E50: 1 | F50: =FALSE() -> FALSE | G50: =IF(OR(F50=TRUE(),F50="TRUE"),0,E50) -> 1 | H50: 26.99 | I50: =IF(H50="","",G50*H50) -> 26.99 | J50: Amazon.ca | K50: https://www.amazon.ca/dp/B0CNRSJ1B2 | L50: https://www.amazon.ca/s?k=heat+set+inserts+kit+m3+m4 | M50: 2026-10-08 | N50: Verified amazon.ca price | O50: =IF(AND(J50="Amazon.ca",G50>0,ISERROR(SEARCH("ALTERNATIVE",A50))),MAX(O$1:O49)+1,"") -> 43
A51: Printed parts: filament & inserts | B51: Metric socket screw assortment M2-M5 (1760 pcs) | C51: Covers M3x20 (hub), M3x12, M4x12/16/20/25 (TD2220, monitors, clamps). Check M4 lengths vs your VESA inserts | Listing: "Besitu 1760pcs M2 M3 M4 M5 Metric Screw Assortment, Grade 12.9 Alloy Steel Hex Socket Head Cap Metri" | D51: Printed-part and display screws | E51: 1 | F51: =FALSE() -> FALSE | G51: =IF(OR(F51=TRUE(),F51="TRUE"),0,E51) -> 1 | H51: 28.99 | I51: =IF(H51="","",G51*H51) -> 28.99 | J51: Amazon.ca | K51: https://www.amazon.ca/dp/B0C38YFL3D | L51: https://www.amazon.ca/s?k=m2+m3+m4+m5+socket+head+screw+assortment | M51: 2026-10-08 | N51: Verified amazon.ca price | O51: =IF(AND(J51="Amazon.ca",G51>0,ISERROR(SEARCH("ALTERNATIVE",A51))),MAX(O$1:O50)+1,"") -> 44
A52: Printed parts: filament & inserts | B52: Self-tapping screw assortment M2 / M2.5 / M3 | C52: 12x M2.5x6 (perfboards) + 12x M3x10 (enclosure lids) | Listing: "1200Pcs M2 M2.5 M3 Small Phillips Flat Head Self Tapping Screws for Wood,Plastic and Soft Metal,Coun" | D52: ESP32 enclosures | E52: 1 | F52: =FALSE() -> FALSE | G52: =IF(OR(F52=TRUE(),F52="TRUE"),0,E52) -> 1 | H52: 16.99 | I52: =IF(H52="","",G52*H52) -> 16.99 | J52: Amazon.ca | K52: https://www.amazon.ca/dp/B09CT54JJZ | L52: https://www.amazon.ca/s?k=self+tapping+screw+assortment+m2.5+m3 | M52: 2026-10-08 | N52: Verified amazon.ca price | O52: =IF(AND(J52="Amazon.ca",G52>0,ISERROR(SEARCH("ALTERNATIVE",A52))),MAX(O$1:O51)+1,"") -> 45
A53: Frame lumber & sheet goods | B53: 2x4 SPF stud 8 ft (2438 mm), kiln dried | C53: 22 used by the cut list + 2 spares. 38 x 89 mm (1.5" x 3.5"). Pick straight boards. Kent Fredericton price (South/Bishop Dr and North/Two Nations Crossing, same price) checked 2026-10-09 | D53: Frame (see frame/cut_list.md) | E53: 24 | F53: =FALSE() -> FALSE | G53: =IF(OR(F53=TRUE(),F53="TRUE"),0,E53) -> 24 | H53: 3.98 | I53: =IF(H53="","",G53*H53) -> 95.52 | J53: Kent | K53: https://kent.ca/en/2-x-4-x-8-spf-stud-kiln-dried-1016318 | L53: https://kent.ca/en/search?q=2x4x8+stud | M53: 2026-10-09 | N53: Kent.ca web price (Fredericton store) | O53: =IF(AND(J53="Amazon.ca",G53>0,ISERROR(SEARCH("ALTERNATIVE",A53))),MAX(O$1:O52)+1,"")
... A57: Frame lumber & sheet goods | B57: 6 mm (1/4") hardboard or plywood, 4x8 ft | C57: Small covers / templates. Price shown is Kent 1/4" meranti ply (hardboard is cheaper) | D57: Covers, templates | E57: 1 | F57: =FALSE() -> FALSE | G57: =IF(OR(F57=TRUE(),F57="TRUE"),0,E57) -> 1 | H57: 24.99 | I57: =IF(H57="","",G57*H57) -> 24.99 | J57: Kent | K57: https://kent.ca/en/1-4-x-4-x-8-meranti-plywood-1015821 | L57: https://kent.ca/en/search?q=1%2F4+hardboard+4x8 | M57: 2026-10-09 | N57: Kent.ca web price (Fredericton store) | O57: =IF(AND(J57="Amazon.ca",G57>0,ISERROR(SEARCH("ALTERNATIVE",A57))),MAX(O$1:O56)+1,"")
A58: Fasteners & general hardware | B58: Construction screws 5 x 80 mm (#10 x 3"), 1 box | C58: 2x4 joints, 2 per joint min. | D58: Frame | E58: 1 | F58: =FALSE() -> FALSE | G58: =IF(OR(F58=TRUE(),F58="TRUE"),0,E58) -> 1 | H58: 25 | I58: =IF(H58="","",G58*H58) -> 25 | J58: Kent / Home Depot | L58: https://kent.ca/en/search?q=construction+screws+%2310+x+3 | N58: Estimate - check in store | O58: =IF(AND(J58="Amazon.ca",G58>0,ISERROR(SEARCH("ALTERNATIVE",A58))),MAX(O$1:O57)+1,"")
A59: Fasteners & general hardware | B59: Wood screws 4 x 40 mm (#8 x 1-1/2"), 1 box | C59: Ply to 2x4 | D59: Frame | E59: 1 | F59: =FALSE() -> FALSE | G59: =IF(OR(F59=TRUE(),F59="TRUE"),0,E59) -> 1 | H59: 15 | I59: =IF(H59="","",G59*H59) -> 15 | J59: Kent / Home Depot | L59: https://kent.ca/en/search?q=wood+screws+%238+x+1-1%2F2 | N59: Estimate - check in store | O59: =IF(AND(J59="Amazon.ca",G59>0,ISERROR(SEARCH("ALTERNATIVE",A59))),MAX(O$1:O58)+1,"")
A60: Fasteners & general hardware | B60: Wood screws 4 x 25 mm (#8 x 1"), 1 box | C60: Skins, clips, limit-switch brackets; also the 30x M4x25 countersunk screws for the TD2220 trim laps | D60: Frame, trim ring | E60: 1 | F60: =FALSE() -> FALSE | G60: =IF(OR(F60=TRUE(),F60="TRUE"),0,E60) -> 1 | H60: 12 | I60: =IF(H60="","",G60*H60) -> 12 | J60: Kent / Home Depot | L60: https://kent.ca/en/search?q=wood+screws+%238+x+1 | N60: Estimate - check in store | O60: =IF(AND(J60="Amazon.ca",G60>0,ISERROR(SEARCH("ALTERNATIVE",A60))),MAX(O$1:O59)+1,"")
A61: Fasteners & general hardware | B61: PVA wood glue, 1 L | C61: Cheek laminations, boxes | D61: Frame | E61: 1 | F61: =FALSE() -> FALSE | G61: =IF(OR(F61=TRUE(),F61="TRUE"),0,E61) -> 1 | H61: 15 | I61: =IF(H61="","",G61*H61) -> 15 | J61: Kent / Home Depot | L61: https://kent.ca/en/search?q=wood+glue+1+l | N61: Estimate - check in store | O61: =IF(AND(J61="Amazon.ca",G61>0,ISERROR(SEARCH("ALTERNATIVE",A61))),MAX(O$1:O60)+1,"")
A62: Fasteners & general hardware | B62: M5 four-prong T-nuts, M5 x 8 mm, 200 pcs | C62: Drill the barrel hole (~7 mm, check) on the 40 mm grid, press in from the back | Listing: "M4 M5 M6 M8 M10 M12 Carbon Steel 4 Prongs T Nut Tee Nuts Furniture Wood Insert (200,M5 x 8mm)" | D62: Panel bays | E62: 1 | F62: =FALSE() -> FALSE | G62: =IF(OR(F62=TRUE(),F62="TRUE"),0,E62) -> 1 | H62: 44.38 | I62: =IF(H62="","",G62*H62) -> 44.38 | J62: Amazon.ca | K62: https://www.amazon.ca/dp/B0FF4HDSK3 | L62: https://www.amazon.ca/s?k=m5+tee+nut+4+prong+200 | M62: 2026-10-08 | N62: Verified amazon.ca price | O62: =IF(AND(J62="Amazon.ca",G62>0,ISERROR(SEARCH("ALTERNATIVE",A62))),MAX(O$1:O61)+1,"") -> 46
A63: Fasteners & general hardware | B63: M5 x 20 flanged button-head socket screws, black, 50 pcs | C63: 200 needed -> 4 packs (flanged, washers optional) | Listing: "50Pcs M5 x 20mm Flanged Button Head Socket Cap Screws Bolts, Allen Socket Drive M5 Screws Bolts Blac" | D63: Panels into T-nuts | E63: 4 | F63: =FALSE() -> FALSE | G63: =IF(OR(F63=TRUE(),F63="TRUE"),0,E63) -> 4 | H63: 14.99 | I63: =IF(H63="","",G63*H63) -> 59.96 | J63: Amazon.ca | K63: https://www.amazon.ca/dp/B0FR1FQ1B7 | L63: https://www.amazon.ca/s?k=m5+x+20+button+head+socket+screw+black | M63: 2026-10-08 | N63: Verified amazon.ca price | O63: =IF(AND(J63="Amazon.ca",G63>0,ISERROR(SEARCH("ALTERNATIVE",A63))),MAX(O$1:O62)+1,"") -> 47
...

Sheet Summary
A1: Category | B1: Lines | C1: Lines still to buy | D1: Total to buy CAD
A2: Computer & displays (owned) | B2: =COUNTIF(BOM!$A$2:$A$110,A2) -> 6 | C2: =COUNTIFS(BOM!$A$2:$A$110,A2,BOM!$G$2:$G$110,">0") -> 0 | D2: =SUMIF(BOM!$A$2:$A$110,A2,BOM!$I$2:$I$110) -> 0
A3: Video & USB cabling | B3: =COUNTIF(BOM!$A$2:$A$110,A3) -> 7 | C3: =COUNTIFS(BOM!$A$2:$A$110,A3,BOM!$G$2:$G$110,">0") -> 7 | D3: =SUMIF(BOM!$A$2:$A$110,A3,BOM!$I$2:$I$110) -> 123.69
A4: Controllers & logic | B4: =COUNTIF(BOM!$A$2:$A$110,A4) -> 16 | C4: =COUNTIFS(BOM!$A$2:$A$110,A4,BOM!$G$2:$G$110,">0") -> 16 | D4: =SUMIF(BOM!$A$2:$A$110,A4,BOM!$I$2:$I$110) -> 295.28
A5: Panel controls | B5: =COUNTIF(BOM!$A$2:$A$110,A5) -> 9 | C5: =COUNTIFS(BOM!$A$2:$A$110,A5,BOM!$G$2:$G$110,">0") -> 9 | D5: =SUMIF(BOM!$A$2:$A$110,A5,BOM!$I$2:$I$110) -> 198.92
A6: LED backlighting | B6: =COUNTIF(BOM!$A$2:$A$110,A6) -> 8 | C6: =COUNTIFS(BOM!$A$2:$A$110,A6,BOM!$G$2:$G$110,">0") -> 8 | D6: =SUMIF(BOM!$A$2:$A$110,A6,BOM!$I$2:$I$110) -> 177.14
A7: Printed parts: filament & inserts | B7: =COUNTIF(BOM!$A$2:$A$110,A7) -> 5 | C7: =COUNTIFS(BOM!$A$2:$A$110,A7,BOM!$G$2:$G$110,">0") -> 5 | D7: =SUMIF(BOM!$A$2:$A$110,A7,BOM!$I$2:$I$110) -> 213.5
A8: Frame lumber & sheet goods | B8: =COUNTIF(BOM!$A$2:$A$110,A8) -> 5 | C8: =COUNTIFS(BOM!$A$2:$A$110,A8,BOM!$G$2:$G$110,">0") -> 5 | D8: =SUMIF(BOM!$A$2:$A$110,A8,BOM!$I$2:$I$110) -> 676.07
A9: Fasteners & general hardware | B9: =COUNTIF(BOM!$A$2:$A$110,A9) -> 10 | C9: =COUNTIFS(BOM!$A$2:$A$110,A9,BOM!$G$2:$G$110,">0") -> 10 | D9: =SUMIF(BOM!$A$2:$A$110,A9,BOM!$I$2:$I$110) -> 207.32
A10: Motion system: pivots, shafts, bearings | B10: =COUNTIF(BOM!$A$2:$A$110,A10) -> 9 | C10: =COUNTIFS(BOM!$A$2:$A$110,A10,BOM!$G$2:$G$110,">0") -> 9 | D10: =SUMIF(BOM!$A$2:$A$110,A10,BOM!$I$2:$I$110) -> 295.28
A11: Motion system: drive & locks | B11: =COUNTIF(BOM!$A$2:$A$110,A11) -> 12 | C11: =COUNTIFS(BOM!$A$2:$A$110,A11,BOM!$G$2:$G$110,">0") -> 12 | D11: =SUMIF(BOM!$A$2:$A$110,A11,BOM!$I$2:$I$110) -> 519.44
A12: Motion system: hardwired interlock | B12: =COUNTIF(BOM!$A$2:$A$110,A12) -> 11 | C12: =COUNTIFS(BOM!$A$2:$A$110,A12,BOM!$G$2:$G$110,">0") -> 11 | D12: =SUMIF(BOM!$A$2:$A$110,A12,BOM!$I$2:$I$110) -> 388.84
A13: Motion system: guards | B13: =COUNTIF(BOM!$A$2:$A$110,A13) -> 2 | C13: =COUNTIFS(BOM!$A$2:$A$110,A13,BOM!$G$2:$G$110,">0") -> 2 | D13: =SUMIF(BOM!$A$2:$A$110,A13,BOM!$I$2:$I$110) -> 92.15
... A15: Seats & harnesses - ALTERNATIVE (not in totals) | B15: =COUNTIF(BOM!$A$2:$A$110,A15) -> 1 | C15: =COUNTIFS(BOM!$A$2:$A$110,A15,BOM!$G$2:$G$110,">0") -> 1 | D15: =SUMIF(BOM!$A$2:$A$110,A15,BOM!$I$2:$I$110) -> 111.98
A17: GRAND TOTAL to buy (excl. ALTERNATIVE rows) | C17: =SUMPRODUCT((ISERROR(SEARCH("ALTERNATIVE",A2:A15)))*C2:C15) -> 102 | D17: =SUMPRODUCT((ISERROR(SEARCH("ALTERNATIVE",A2:A15)))*D2:D15) -> 3435.8
A18: of which Amazon.ca | D18: =SUMPRODUCT((BOM!$J$2:$J$110="Amazon.ca")*ISERROR(SEARCH("ALTERNATIVE",BOM!$A$2:$A$110))*N(+BOM!$I$2:$I$110)) -> 2168.73
A19: of which Kent / Home Depot | D19: =SUMPRODUCT(ISNUMBER(SEARCH("Kent",BOM!$J$2:$J$110))*N(+BOM!$I$2:$I$110)) -> 912.07
A20: of which local / industrial suppliers | D20: =SUMPRODUCT((ISNUMBER(SEARCH("supplier",BOM!$J$2:$J$110)))*N(+BOM!$I$2:$I$110)) -> 355
A21: of which based on VERIFIED prices (amazon.ca / kent.ca) | D21: =SUMPRODUCT((ISNUMBER(SEARCH("Verified amazon.ca price",BOM!$N$2:$N$110))+ISNUMBER(SEARCH("Kent.ca web price",BOM!$N$2:$N$110))>0)*ISERROR(SEARCH("ALTERNATIVE",BOM!$A$2:$A$110))*N(+BOM!$I$2:$I$110)) -> 2691.8
A22: of which ESTIMATES / placeholders | D22: =SUMPRODUCT((ISNUMBER(SEARCH("estimate",BOM!$N$2:$N$110)))*ISERROR(SEARCH("ALTERNATIVE",BOM!$A$2:$A$110))*N(+BOM!$I$2:$I$110)) -> 744
A23: ALTERNATIVE rated harness option (if chosen) | D23: =SUMPRODUCT(ISNUMBER(SEARCH("ALTERNATIVE",BOM!$A$2:$A$110))*N(+BOM!$I$2:$I$110)) -> 111.98
A25: Totals update automatically when you change "Have it" on the BOM sheet (TRUE = already owned -> Qty to buy 0).
A26: Prices are before tax/shipping (NB HST 15 %). Amazon prices change daily; dates are in the BOM sheet.

Sheet Amazon cart
A1: # | B1: Item | C1: Qty to buy | D1: Unit price CAD | E1: Line total | F1: Link | G1: Search link | I1: Lists only Amazon.ca rows with Qty to buy > 0 (alternatives excluded). Built with INDEX/MATCH on a hidden helper column (BOM!O) so it works in every LibreOffice and Excel version (FILTER needs LO 24.8+/Excel 365). Updates when Have it changes.
A2: =IF(ISNA(MATCH(1,BOM!$O$2:$O$110,0)),"",1) -> 1 | B2: =IF($A2="","",INDEX(BOM!$B$2:$B$110,MATCH(1,BOM!$O$2:$O$110,0))) -> DisplayPort 1.4 cable, 3 m (10 ft), VESA certified | C2: =IF($A2="","",INDEX(BOM!$G$2:$G$110,MATCH(1,BOM!$O$2:$O$110,0))) -> 1 | D2: =IF($A2="","",INDEX(BOM!$H$2:$H$110,MATCH(1,BOM!$O$2:$O$110,0))) -> 16.99 | E2: =IF($A2="","",INDEX(BOM!$I$2:$I$110,MATCH(1,BOM!$O$2:$O$110,0))) -> 16.99 | F2: =IF($A2="","",IF(INDEX(BOM!$K$2:$K$110,MATCH(1,BOM!$O$2:$O$110,0))="","",HYPERLINK(INDEX(BOM!$K$2:$K$110,MATCH(1,BOM!$O$2:$O$110,0)),"open on amazon.ca"))) -> open on amazon.ca | G2: =IF($A2="","",HYPERLINK(INDEX(BOM!$L$2:$L$110,MATCH(1,BOM!$O$2:$O$110,0)),"search")) -> search
A3: =IF(ISNA(MATCH(2,BOM!$O$2:$O$110,0)),"",2) -> 2 | B3: =IF($A3="","",INDEX(BOM!$B$2:$B$110,MATCH(2,BOM!$O$2:$O$110,0))) -> HDMI cable, 3 m (10 ft) | C3: =IF($A3="","",INDEX(BOM!$G$2:$G$110,MATCH(2,BOM!$O$2:$O$110,0))) -> 1 | D3: =IF($A3="","",INDEX(BOM!$H$2:$H$110,MATCH(2,BOM!$O$2:$O$110,0))) -> 10.76 | E3: =IF($A3="","",INDEX(BOM!$I$2:$I$110,MATCH(2,BOM!$O$2:$O$110,0))) -> 10.76 | F3: =IF($A3="","",IF(INDEX(BOM!$K$2:$K$110,MATCH(2,BOM!$O$2:$O$110,0))="","",HYPERLINK(INDEX(BOM!$K$2:$K$110,MATCH(2,BOM!$O$2:$O$110,0)),"open on amazon.ca"))) -> open on amazon.ca | G3: =IF($A3="","",HYPERLINK(INDEX(BOM!$L$2:$L$110,MATCH(2,BOM!$O$2:$O$110,0)),"search")) -> search
A4: =IF(ISNA(MATCH(3,BOM!$O$2:$O$110,0)),"",3) -> 3 | B4: =IF($A4="","",INDEX(BOM!$B$2:$B$110,MATCH(3,BOM!$O$2:$O$110,0))) -> DisplayPort -> DVI-D adapter cable, passive, 3 m (10 ft) | C4: =IF($A4="","",INDEX(BOM!$G$2:$G$110,MATCH(3,BOM!$O$2:$O$110,0))) -> 1 | D4: =IF($A4="","",INDEX(BOM!$H$2:$H$110,MATCH(3,BOM!$O$2:$O$110,0))) -> 16.99 | E4: =IF($A4="","",INDEX(BOM!$I$2:$I$110,MATCH(3,BOM!$O$2:$O$110,0))) -> 16.99 | F4: =IF($A4="","",IF(INDEX(BOM!$K$2:$K$110,MATCH(3,BOM!$O$2:$O$110,0))="","",HYPERLINK(INDEX(BOM!$K$2:$K$110,MATCH(3,BOM!$O$2:$O$110,0)),"open on amazon.ca"))) -> open on amazon.ca | G4: =IF($A4="","",HYPERLINK(INDEX(BOM!$L$2:$L$110,MATCH(3,BOM!$O$2:$O$110,0)),"search")) -> search
A5: =IF(ISNA(MATCH(4,BOM!$O$2:$O$110,0)),"",4) -> 4 | B5: =IF($A5="","",INDEX(BOM!$B$2:$B$110,MATCH(4,BOM!$O$2:$O$110,0))) -> USB-A to USB-B cable, 3 m (10 ft) | C5: =IF($A5="","",INDEX(BOM!$G$2:$G$110,MATCH(4,BOM!$O$2:$O$110,0))) -> 1 | D5: =IF($A5="","",INDEX(BOM!$H$2:$H$110,MATCH(4,BOM!$O$2:$O$110,0))) -> 12.99 | E5: =IF($A5="","",INDEX(BOM!$I$2:$I$110,MATCH(4,BOM!$O$2:$O$110,0))) -> 12.99 | F5: =IF($A5="","",IF(INDEX(BOM!$K$2:$K$110,MATCH(4,BOM!$O$2:$O$110,0))="","",HYPERLINK(INDEX(BOM!$K$2:$K$110,MATCH(4,BOM!$O$2:$O$110,0)),"open on amazon.ca"))) -> open on amazon.ca | G5: =IF($A5="","",HYPERLINK(INDEX(BOM!$L$2:$L$110,MATCH(4,BOM!$O$2:$O$110,0)),"search")) -> search
A6: =IF(ISNA(MATCH(5,BOM!$O$2:$O$110,0)),"",5) -> 5 | B6: =IF($A6="","",INDEX(BOM!$B$2:$B$110,MATCH(5,BOM!$O$2:$O$110,0))) -> USB-A to USB-C data cables 1.8 m (6 ft), 3-pack | C6: =IF($A6="","",INDEX(BOM!$G$2:$G$110,MATCH(5,BOM!$O$2:$O$110,0))) -> 1 | D6: =IF($A6="","",INDEX(BOM!$H$2:$H$110,MATCH(5,BOM!$O$2:$O$110,0))) -> 9.99 | E6: =IF($A6="","",INDEX(BOM!$I$2:$I$110,MATCH(5,BOM!$O$2:$O$110,0))) -> 9.99 | F6: =IF($A6="","",IF(INDEX(BOM!$K$2:$K$110,MATCH(5,BOM!$O$2:$O$110,0))="","",HYPERLINK(INDEX(BOM!$K$2:$K$110,MATCH(5,BOM!$O$2:$O$110,0)),"open on amazon.ca"))) -> open on amazon.ca | G6: =IF($A6="","",HYPERLINK(INDEX(BOM!$L$2:$L$110,MATCH(5,BOM!$O$2:$O$110,0)),"search")) -> search
A7: =IF(ISNA(MATCH(6,BOM!$O$2:$O$110,0)),"",6) -> 6 | B7: =IF($A7="","",INDEX(BOM!$B$2:$B$110,MATCH(6,BOM!$O$2:$O$110,0))) -> Powered USB 3.0 hub, 7-port, with power adapter | C7: =IF($A7="","",INDEX(BOM!$G$2:$G$110,MATCH(6,BOM!$O$2:$O$110,0))) -> 1 | D7: =IF($A7="","",INDEX(BOM!$H$2:$H$110,MATCH(6,BOM!$O$2:$O$110,0))) -> 39.99 | E7: =IF($A7="","",INDEX(BOM!$I$2:$I$110,MATCH(6,BOM!$O$2:$O$110,0))) -> 39.99 | F7: =IF($A7="","",IF(INDEX(BOM!$K$2:$K$110,MATCH(6,BOM!$O$2:$O$110,0))="","",HYPERLINK(INDEX(BOM!$K$2:$K$110,MATCH(6,BOM!$O$2:$O$110,0)),"open on amazon.ca"))) -> open on amazon.ca | G7: =IF($A7="","",HYPERLINK(INDEX(BOM!$L$2:$L$110,MATCH(6,BOM!$O$2:$O$110,0)),"search")) -> search
A8: =IF(ISNA(MATCH(7,BOM!$O$2:$O$110,0)),"",7) -> 7 | B8: =IF($A8="","",INDEX(BOM!$B$2:$B$110,MATCH(7,BOM!$O$2:$O$110,0))) -> Expandable braided sleeve 25 mm (1"), 7.6 m (25 ft) | C8: =IF($A8="","",INDEX(BOM!$G$2:$G$110,MATCH(7,BOM!$O$2:$O$110,0))) -> 1 | D8: =IF($A8="","",INDEX(BOM!$H$2:$H$110,MATCH(7,BOM!$O$2:$O$110,0))) -> 15.98 | E8: =IF($A8="","",INDEX(BOM!$I$2:$I$110,MATCH(7,BOM!$O$2:$O$110,0))) -> 15.98 | F8: =IF($A8="","",IF(INDEX(BOM!$K$2:$K$110,MATCH(7,BOM!$O$2:$O$110,0))="","",HYPERLINK(INDEX(BOM!$K$2:$K$110,MATCH(7,BOM!$O$2:$O$110,0)),"open on amazon.ca"))) -> open on amazon.ca | G8: =IF($A8="","",HYPERLINK(INDEX(BOM!$L$2:$L$110,MATCH(7,BOM!$O$2:$O$110,0)),"search")) -> search
A9: =IF(ISNA(MATCH(8,BOM!$O$2:$O$110,0)),"",8) -> 8 | B9: =IF($A9="","",INDEX(BOM!$B$2:$B$110,MATCH(8,BOM!$O$2:$O$110,0))) -> ESP32-S3-DevKitC-1-N8R8, 5-pack | C9: =IF($A9="","",INDEX(BOM!$G$2:$G$110,MATCH(8,BOM!$O$2:$O$110,0))) -> 1 | D9: =IF($A9="","",INDEX(BOM!$H$2:$H$110,MATCH(8,BOM!$O$2:$O$110,0))) -> 71.98 | E9: =IF($A9="","",INDEX(BOM!$I$2:$I$110,MATCH(8,BOM!$O$2:$O$110,0))) -> 71.98 | F9: =IF($A9="","",IF(INDEX(BOM!$K$2:$K$110,MATCH(8,BOM!$O$2:$O$110,0))="","",HYPERLINK(INDEX(BOM!$K$2:$K$110,MATCH(8,BOM!$O$2:$O$110,0)),"open on amazon.ca"))) -> open on amazon.ca | G9: =IF($A9="","",HYPERLINK(INDEX(BOM!$L$2:$L$110,MATCH(8,BOM!$O$2:$O$110,0)),"search")) -> search
A10: =IF(ISNA(MATCH(9,BOM!$O$2:$O$110,0)),"",9) -> 9 | B10: =IF($A10="","",INDEX(BOM!$B$2:$B$110,MATCH(9,BOM!$O$2:$O$110,0))) -> 74HC165 shift register DIP-16, 25 pcs | C10: =IF($A10="","",INDEX(BOM!$G$2:$G$110,MATCH(9,BOM!$O$2:$O$110,0))) -> 1 | D10: =IF($A10="","",INDEX(BOM!$H$2:$H$110,MATCH(9,BOM!$O$2:$O$110,0))) -> 18.49 | E10: =IF($A10="","",INDEX(BOM!$I$2:$I$110,MATCH(9,BOM!$O$2:$O$110,0))) -> 18.49 | F10: =IF($A10="","",IF(INDEX(BOM!$K$2:$K$110,MATCH(9,BOM!$O$2:$O$110,0))="","",HYPERLINK(INDEX(BOM!$K$2:$K$110,MATCH(9,BOM!$O$2:$O$110,0)),"open on amazon.ca"))) -> open on amazon.ca | G10: =IF($A10="","",HYPERLINK(INDEX(BOM!$L$2:$L$110,MATCH(9,BOM!$O$2:$O$110,0)),"search")) -> search
A11: =IF(ISNA(MATCH(10,BOM!$O$2:$O$110,0)),"",10) -> 10 | B11: =IF($A11="","",INDEX(BOM!$B$2:$B$110,MATCH(10,BOM!$O$2:$O$110,0))) -> DIP IC socket assortment (incl. 14- and 16-pin) | C11: =IF($A11="","",INDEX(BOM!$G$2:$G$110,MATCH(10,BOM!$O$2:$O$110,0))) -> 1 | D11: =IF($A11="","",INDEX(BOM!$H$2:$H$110,MATCH(10,BOM!$O$2:$O$110,0))) -> 16.99 | E11: =IF($A11="","",INDEX(BOM!$I$2:$I$110,MATCH(10,BOM!$O$2:$O$110,0))) -> 16.99 | F11: =IF($A11="","",IF(INDEX(BOM!$K$2:$K$110,MATCH(10,BOM!$O$2:$O$110,0))="","",HYPERLINK(INDEX(BOM!$K$2:$K$110,MATCH(10,BOM!$O$2:$O$110,0)),"open on amazon.ca"))) -> open on amazon.ca | G11: =IF($A11="","",HYPERLINK(INDEX(BOM!$L$2:$L$110,MATCH(10,BOM!$O$2:$O$110,0)),"search")) -> search
A12: =IF(ISNA(MATCH(11,BOM!$O$2:$O$110,0)),"",11) -> 11 | B12: =IF($A12="","",INDEX(BOM!$B$2:$B$110,MATCH(11,BOM!$O$2:$O$110,0))) -> 10 kOhm bussed resistor network SIP-9 (A103J), 20 pcs | C12: =IF($A12="","",INDEX(BOM!$G$2:$G$110,MATCH(11,BOM!$O$2:$O$110,0))) -> 1 | D12: =IF($A12="","",INDEX(BOM!$H$2:$H$110,MATCH(11,BOM!$O$2:$O$110,0))) -> 8.88 | E12: =IF($A12="","",INDEX(BOM!$I$2:$I$110,MATCH(11,BOM!$O$2:$O$110,0))) -> 8.88 | F12: =IF($A12="","",IF(INDEX(BOM!$K$2:$K$110,MATCH(11,BOM!$O$2:$O$110,0))="","",HYPERLINK(INDEX(BOM!$K$2:$K$110,MATCH(11,BOM!$O$2:$O$110,0)),"open on amazon.ca"))) -> open on amazon.ca | G12: =IF($A12="","",HYPERLINK(INDEX(BOM!$L$2:$L$110,MATCH(11,BOM!$O$2:$O$110,0)),"search")) -> search
A13: =IF(ISNA(MATCH(12,BOM!$O$2:$O$110,0)),"",12) -> 12 | B13: =IF($A13="","",INDEX(BOM!$B$2:$B$110,MATCH(12,BOM!$O$2:$O$110,0))) -> 100 nF ceramic capacitors, 100 pcs | C13: =IF($A13="","",INDEX(BOM!$G$2:$G$110,MATCH(12,BOM!$O$2:$O$110,0))) -> 1 | D13: =IF($A13="","",INDEX(BOM!$H$2:$H$110,MATCH(12,BOM!$O$2:$O$110,0))) -> 6.55 | E13: =IF($A13="","",INDEX(BOM!$I$2:$I$110,MATCH(12,BOM!$O$2:$O$110,0))) -> 6.55 | F13: =IF($A13="","",IF(INDEX(BOM!$K$2:$K$110,MATCH(12,BOM!$O$2:$O$110,0))="","",HYPERLINK(INDEX(BOM!$K$2:$K$110,MATCH(12,BOM!$O$2:$O$110,0)),"open on amazon.ca"))) -> open on amazon.ca | G13: =IF($A13="","",HYPERLINK(INDEX(BOM!$L$2:$L$110,MATCH(12,BOM!$O$2:$O$110,0)),"search")) -> search
A14: =IF(ISNA(MATCH(13,BOM!$O$2:$O$110,0)),"",13) -> 13 | B14: =IF($A14="","",INDEX(BOM!$B$2:$B$110,MATCH(13,BOM!$O$2:$O$110,0))) -> Electrolytic capacitor assortment 0.1-1000 uF (10-50 V) | C14: =IF($A14="","",INDEX(BOM!$G$2:$G$110,MATCH(13,BOM!$O$2:$O$110,0))) -> 1 | D14: =IF($A14="","",INDEX(BOM!$H$2:$H$110,MATCH(13,BOM!$O$2:$O$110,0))) -> 16.99 | E14: =IF($A14="","",INDEX(BOM!$I$2:$I$110,MATCH(13,BOM!$O$2:$O$110,0))) -> 16.99 | F14: =IF($A14="","",IF(INDEX(BOM!$K$2:$K$110,MATCH(13,BOM!$O$2:$O$110,0))="","",HYPERLINK(INDEX(BOM!$K$2:$K$110,MATCH(13,BOM!$O$2:$O$110,0)),"open on amazon.ca"))) -> open on amazon.ca | G14: =IF($A14="","",HYPERLINK(INDEX(BOM!$L$2:$L$110,MATCH(13,BOM!$O$2:$O$110,0)),"search")) -> search
A15: =IF(ISNA(MATCH(14,BOM!$O$2:$O$110,0)),"",14) -> 14 | B15: =IF($A15="","",INDEX(BOM!$B$2:$B$110,MATCH(14,BOM!$O$2:$O$110,0))) -> 74AHCT125N DIP-14 level shifter, 10 pcs | C15: =IF($A15="","",INDEX(BOM!$G$2:$G$110,MATCH(14,BOM!$O$2:$O$110,0))) -> 1 | D15: =IF($A15="","",INDEX(BOM!$H$2:$H$110,MATCH(14,BOM!$O$2:$O$110,0))) -> 11.56 | E15: =IF($A15="","",INDEX(BOM!$I$2:$I$110,MATCH(14,BOM!$O$2:$O$110,0))) -> 11.56 | F15: =IF($A15="","",IF(INDEX(BOM!$K$2:$K$110,MATCH(14,BOM!$O$2:$O$110,0))="","",HYPERLINK(INDEX(BOM!$K$2:$K$110,MATCH(14,BOM!$O$2:$O$110,0)),"open on amazon.ca"))) -> open on amazon.ca | G15: =IF($A15="","",HYPERLINK(INDEX(BOM!$L$2:$L$110,MATCH(14,BOM!$O$2:$O$110,0)),"search")) -> search
A16: =IF(ISNA(MATCH(15,BOM!$O$2:$O$110,0)),"",15) -> 15 | B16: =IF($A16="","",INDEX(BOM!$B$2:$B$110,MATCH(15,BOM!$O$2:$O$110,0))) -> Resistor kit 1/4 W 1%, 50 values | C16: =IF($A16="","",INDEX(BOM!$G$2:$G$110,MATCH(15,BOM!$O$2:$O$110,0))) -> 1 | D16: =IF($A16="","",INDEX(BOM!$H$2:$H$110,MATCH(15,BOM!$O$2:$O$110,0))) -> 19.99 | E16: =IF($A16="","",INDEX(BOM!$I$2:$I$110,MATCH(15,BOM!$O$2:$O$110,0))) -> 19.99 | F16: =IF($A16="","",IF(INDEX(BOM!$K$2:$K$110,MATCH(15,BOM!$O$2:$O$110,0))="","",HYPERLINK(INDEX(BOM!$K$2:$K$110,MATCH(15,BOM!$O$2:$O$110,0)),"open on amazon.ca"))) -> open on amazon.ca | G16: =IF($A16="","",HYPERLINK(INDEX(BOM!$L$2:$L$110,MATCH(15,BOM!$O$2:$O$110,0)),"search")) -> search
A17: =IF(ISNA(MATCH(16,BOM!$O$2:$O$110,0)),"",16) -> 16 | B17: =IF($A17="","",INDEX(BOM!$B$2:$B$110,MATCH(16,BOM!$O$2:$O$110,0))) -> 2.2 kOhm 1/2 W resistors, 10 pcs | C17: =IF($A17="","",INDEX(BOM!$G$2:$G$110,MATCH(16,BOM!$O$2:$O$110,0))) -> 1 | D17: =IF($A17="","",INDEX(BOM!$H$2:$H$110,MATCH(16,BOM!$O$2:$O$110,0))) -> 8.76 | E17: =IF($A17="","",INDEX(BOM!$I$2:$I$110,MATCH(16,BOM!$O$2:$O$110,0))) -> 8.76 | F17: =IF($A17="","",IF(INDEX(BOM!$K$2:$K$110,MATCH(16,BOM!$O$2:$O$110,0))="","",HYPERLINK(INDEX(BOM!$K$2:$K$110,MATCH(16,BOM!$O$2:$O$110,0)),"open on amazon.ca"))) -> open on amazon.ca | G17: =IF($A17="","",HYPERLINK(INDEX(BOM!$L$2:$L$110,MATCH(16,BOM!$O$2:$O$110,0)),"search")) -> search
A18: =IF(ISNA(MATCH(17,BOM!$O$2:$O$110,0)),"",17) -> 17 | B18: =IF($A18="","",INDEX(BOM!$B$2:$B$110,MATCH(17,BOM!$O$2:$O$110,0))) -> PC817 optocoupler DIP-4, 20 pcs | C18: =IF($A18="","",INDEX(BOM!$G$2:$G$110,MATCH(17,BOM!$O$2:$O$110,0))) -> 1 | D18: =IF($A18="","",INDEX(BOM!$H$2:$H$110,MATCH(17,BOM!$O$2:$O$110,0))) -> 10.68 | E18: =IF($A18="","",INDEX(BOM!$I$2:$I$110,MATCH(17,BOM!$O$2:$O$110,0))) -> 10.68 | F18: =IF($A18="","",IF(INDEX(BOM!$K$2:$K$110,MATCH(17,BOM!$O$2:$O$110,0))="","",HYPERLINK(INDEX(BOM!$K$2:$K$110,MATCH(17,BOM!$O$2:$O$110,0)),"open on amazon.ca"))) -> open on amazon.ca | G18: =IF($A18="","",HYPERLINK(INDEX(BOM!$L$2:$L$110,MATCH(17,BOM!$O$2:$O$110,0)),"search")) -> search
A19: =IF(ISNA(MATCH(18,BOM!$O$2:$O$110,0)),"",18) -> 18 | B19: =IF($A19="","",INDEX(BOM!$B$2:$B$110,MATCH(18,BOM!$O$2:$O$110,0))) -> Perfboard 7 x 9 cm, 10 pcs | C19: =IF($A19="","",INDEX(BOM!$G$2:$G$110,MATCH(18,BOM!$O$2:$O$110,0))) -> 1 | D19: =IF($A19="","",INDEX(BOM!$H$2:$H$110,MATCH(18,BOM!$O$2:$O$110,0))) -> 12.96 | E19: =IF($A19="","",INDEX(BOM!$I$2:$I$110,MATCH(18,BOM!$O$2:$O$110,0))) -> 12.96 | F19: =IF($A19="","",IF(INDEX(BOM!$K$2:$K$110,MATCH(18,BOM!$O$2:$O$110,0))="","",HYPERLINK(INDEX(BOM!$K$2:$K$110,MATCH(18,BOM!$O$2:$O$110,0)),"open on amazon.ca"))) -> open on amazon.ca | G19: =IF($A19="","",HYPERLINK(INDEX(BOM!$L$2:$L$110,MATCH(18,BOM!$O$2:$O$110,0)),"search")) -> search
A20: =IF(ISNA(MATCH(19,BOM!$O$2:$O$110,0)),"",19) -> 19 | B20: =IF($A20="","",INDEX(BOM!$B$2:$B$110,MATCH(19,BOM!$O$2:$O$110,0))) -> 2.54 mm male + female pin header kit | C20: =IF($A20="","",INDEX(BOM!$G$2:$G$110,MATCH(19,BOM!$O$2:$O$110,0))) -> 1 | D20: =IF($A20="","",INDEX(BOM!$H$2:$H$110,MATCH(19,BOM!$O$2:$O$110,0))) -> 18.99 | E20: =IF($A20="","",INDEX(BOM!$I$2:$I$110,MATCH(19,BOM!$O$2:$O$110,0))) -> 18.99 | F20: =IF($A20="","",IF(INDEX(BOM!$K$2:$K$110,MATCH(19,BOM!$O$2:$O$110,0))="","",HYPERLINK(INDEX(BOM!$K$2:$K$110,MATCH(19,BOM!$O$2:$O$110,0)),"open on amazon.ca"))) -> open on amazon.ca | G20: =IF($A20="","",HYPERLINK(INDEX(BOM!$L$2:$L$110,MATCH(19,BOM!$O$2:$O$110,0)),"search")) -> search
A21: =IF(ISNA(MATCH(20,BOM!$O$2:$O$110,0)),"",20) -> 20 | B21: =IF($A21="","",INDEX(BOM!$B$2:$B$110,MATCH(20,BOM!$O$2:$O$110,0))) -> JST-XH 2.54 mm connector kit with pre-crimped leads | C21: =IF($A21="","",INDEX(BOM!$G$2:$G$110,MATCH(20,BOM!$O$2:$O$110,0))) -> 1 | D21: =IF($A21="","",INDEX(BOM!$H$2:$H$110,MATCH(20,BOM!$O$2:$O$110,0))) -> 20.99 | E21: =IF($A21="","",INDEX(BOM!$I$2:$I$110,MATCH(20,BOM!$O$2:$O$110,0))) -> 20.99 | F21: =IF($A21="","",IF(INDEX(BOM!$K$2:$K$110,MATCH(20,BOM!$O$2:$O$110,0))="","",HYPERLINK(INDEX(BOM!$K$2:$K$110,MATCH(20,BOM!$O$2:$O$110,0)),"open on amazon.ca"))) -> open on amazon.ca | G21: =IF($A21="","",HYPERLINK(INDEX(BOM!$L$2:$L$110,MATCH(20,BOM!$O$2:$O$110,0)),"search")) -> search
A22: =IF(ISNA(MATCH(21,BOM!$O$2:$O$110,0)),"",21) -> 21 | B22: =IF($A22="","",INDEX(BOM!$B$2:$B$110,MATCH(21,BOM!$O$2:$O$110,0))) -> Dupont jumper wires, 120 pcs | C22: =IF($A22="","",INDEX(BOM!$G$2:$G$110,MATCH(21,BOM!$O$2:$O$110,0))) -> 1 | D22: =IF($A22="","",INDEX(BOM!$H$2:$H$110,MATCH(21,BOM!$O$2:$O$110,0))) -> 12.99 | E22: =IF($A22="","",INDEX(BOM!$I$2:$I$110,MATCH(21,BOM!$O$2:$O$110,0))) -> 12.99 | F22: =IF($A22="","",IF(INDEX(BOM!$K$2:$K$110,MATCH(21,BOM!$O$2:$O$110,0))="","",HYPERLINK(INDEX(BOM!$K$2:$K$110,MATCH(21,BOM!$O$2:$O$110,0)),"open on amazon.ca"))) -> open on amazon.ca | G22: =IF($A22="","",HYPERLINK(INDEX(BOM!$L$2:$L$110,MATCH(21,BOM!$O$2:$O$110,0)),"search")) -> search
A23: =IF(ISNA(MATCH(22,BOM!$O$2:$O$110,0)),"",22) -> 22 | B23: =IF($A23="","",INDEX(BOM!$B$2:$B$110,MATCH(22,BOM!$O$2:$O$110,0))) -> Cat6 patch cable 7.6 m (25 ft) | C23: =IF($A23="","",INDEX(BOM!$G$2:$G$110,MATCH(22,BOM!$O$2:$O$110,0))) -> 1 | D23: =IF($A23="","",INDEX(BOM!$H$2:$H$110,MATCH(22,BOM!$O$2:$O$110,0))) -> 17.99 | E23: =IF($A23="","",INDEX(BOM!$I$2:$I$110,MATCH(22,BOM!$O$2:$O$110,0))) -> 17.99 | F23: =IF($A23="","",IF(INDEX(BOM!$K$2:$K$110,MATCH(22,BOM!$O$2:$O$110,0))="","",HYPERLINK(INDEX(BOM!$K$2:$K$110,MATCH(22,BOM!$O$2:$O$110,0)),"open on amazon.ca"))) -> open on amazon.ca | G23: =IF($A23="","",HYPERLINK(INDEX(BOM!$L$2:$L$110,MATCH(22,BOM!$O$2:$O$110,0)),"search")) -> search
A24: =IF(ISNA(MATCH(23,BOM!$O$2:$O$110,0)),"",23) -> 23 | B24: =IF($A24="","",INDEX(BOM!$B$2:$B$110,MATCH(23,BOM!$O$2:$O$110,0))) -> 22 AWG stranded hookup wire kit (6 colours) | C24: =IF($A24="","",INDEX(BOM!$G$2:$G$110,MATCH(23,BOM!$O$2:$O$110,0))) -> 1 | D24: =IF($A24="","",INDEX(BOM!$H$2:$H$110,MATCH(23,BOM!$O$2:$O$110,0))) -> 20.49 | E24: =IF($A24="","",INDEX(BOM!$I$2:$I$110,MATCH(23,BOM!$O$2:$O$110,0))) -> 20.49 | F24: =IF($A24="","",IF(INDEX(BOM!$K$2:$K$110,MATCH(23,BOM!$O$2:$O$110,0))="","",HYPERLINK(INDEX(BOM!$K$2:$K$110,MATCH(23,BOM!$O$2:$O$110,0)),"open on amazon.ca"))) -> open on amazon.ca | G24: =IF($A24="","",HYPERLINK(INDEX(BOM!$L$2:$L$110,MATCH(23,BOM!$O$2:$O$110,0)),"search")) -> search
A25: =IF(ISNA(MATCH(24,BOM!$O$2:$O$110,0)),"",24) -> 24 | B25: =IF($A25="","",INDEX(BOM!$B$2:$B$110,MATCH(24,BOM!$O$2:$O$110,0))) -> Mini toggle switch MTS-102, 6 mm (1/4") bushing, 10 pcs | C25: =IF($A25="","",INDEX(BOM!$G$2:$G$110,MATCH(24,BOM!$O$2:$O$110,0))) -> 3 | D25: =IF($A25="","",INDEX(BOM!$H$2:$H$110,MATCH(24,BOM!$O$2:$O$110,0))) -> 8.45 | E25: =IF($A25="","",INDEX(BOM!$I$2:$I$110,MATCH(24,BOM!$O$2:$O$110,0))) -> 25.35 | F25: =IF($A25="","",IF(INDEX(BOM!$K$2:$K$110,MATCH(24,BOM!$O$2:$O$110,0))="","",HYPERLINK(INDEX(BOM!$K$2:$K$110,MATCH(24,BOM!$O$2:$O$110,0)),"open on amazon.ca"))) -> open on amazon.ca | G25: =IF($A25="","",HYPERLINK(INDEX(BOM!$L$2:$L$110,MATCH(24,BOM!$O$2:$O$110,0)),"search")) -> search
A26: =IF(ISNA(MATCH(25,BOM!$O$2:$O$110,0)),"",25) -> 25 | B26: =IF($A26="","",INDEX(BOM!$B$2:$B$110,MATCH(25,BOM!$O$2:$O$110,0))) -> Mini toggle MTS-103 ON-OFF-ON, 6 mm bushing, 10 pcs | C26: =IF($A26="","",INDEX(BOM!$G$2:$G$110,MATCH(25,BOM!$O$2:$O$110,0))) -> 1 | D26: =IF($A26="","",INDEX(BOM!$H$2:$H$110,MATCH(25,BOM!$O$2:$O$110,0))) -> 12.99 | E26: =IF($A26="","",INDEX(BOM!$I$2:$I$110,MATCH(25,BOM!$O$2:$O$110,0))) -> 12.99 | F26: =IF($A26="","",IF(INDEX(BOM!$K$2:$K$110,MATCH(25,BOM!$O$2:$O$110,0))="","",HYPERLINK(INDEX(BOM!$K$2:$K$110,MATCH(25,BOM!$O$2:$O$110,0)),"open on amazon.ca"))) -> open on amazon.ca | G26: =IF($A26="","",HYPERLINK(INDEX(BOM!$L$2:$L$110,MATCH(25,BOM!$O$2:$O$110,0)),"search")) -> search
A27: =IF(ISNA(MATCH(26,BOM!$O$2:$O$110,0)),"",26) -> 26 | B27: =IF($A27="","",INDEX(BOM!$B$2:$B$110,MATCH(26,BOM!$O$2:$O$110,0))) -> 22 mm momentary push buttons (LA38, 5 colours), 6 pcs | C27: =IF($A27="","",INDEX(BOM!$G$2:$G$110,MATCH(26,BOM!$O$2:$O$110,0))) -> 2 | D27: =IF($A27="","",INDEX(BOM!$H$2:$H$110,MATCH(26,BOM!$O$2:$O$110,0))) -> 19.49 | E27: =IF($A27="","",INDEX(BOM!$I$2:$I$110,MATCH(26,BOM!$O$2:$O$110,0))) -> 38.98 | F27: =IF($A27="","",IF(INDEX(BOM!$K$2:$K$110,MATCH(26,BOM!$O$2:$O$110,0))="","",HYPERLINK(INDEX(BOM!$K$2:$K$110,MATCH(26,BOM!$O$2:$O$110,0)),"open on amazon.ca"))) -> open on amazon.ca | G27: =IF($A27="","",HYPERLINK(INDEX(BOM!$L$2:$L$110,MATCH(26,BOM!$O$2:$O$110,0)),"search")) -> search
A28: =IF(ISNA(MATCH(27,BOM!$O$2:$O$110,0)),"",27) -> 27 | B28: =IF($A28="","",INDEX(BOM!$B$2:$B$110,MATCH(27,BOM!$O$2:$O$110,0))) -> 19 mm momentary metal push buttons, 2 pcs | C28: =IF($A28="","",INDEX(BOM!$G$2:$G$110,MATCH(27,BOM!$O$2:$O$110,0))) -> 2 | D28: =IF($A28="","",INDEX(BOM!$H$2:$H$110,MATCH(27,BOM!$O$2:$O$110,0))) -> 15.39 | E28: =IF($A28="","",INDEX(BOM!$I$2:$I$110,MATCH(27,BOM!$O$2:$O$110,0))) -> 30.78 | F28: =IF($A28="","",IF(INDEX(BOM!$K$2:$K$110,MATCH(27,BOM!$O$2:$O$110,0))="","",HYPERLINK(INDEX(BOM!$K$2:$K$110,MATCH(27,BOM!$O$2:$O$110,0)),"open on amazon.ca"))) -> open on amazon.ca | G28: =IF($A28="","",HYPERLINK(INDEX(BOM!$L$2:$L$110,MATCH(27,BOM!$O$2:$O$110,0)),"search")) -> search
A29: =IF(ISNA(MATCH(28,BOM!$O$2:$O$110,0)),"",28) -> 28 | B29: =IF($A29="","",INDEX(BOM!$B$2:$B$110,MATCH(28,BOM!$O$2:$O$110,0))) -> 16 mm momentary metal push buttons, 5 pcs | C29: =IF($A29="","",INDEX(BOM!$G$2:$G$110,MATCH(28,BOM!$O$2:$O$110,0))) -> 2 | D29: =IF($A29="","",INDEX(BOM!$H$2:$H$110,MATCH(28,BOM!$O$2:$O$110,0))) -> 11.99 | E29: =IF($A29="","",INDEX(BOM!$I$2:$I$110,MATCH(28,BOM!$O$2:$O$110,0))) -> 23.98 | F29: =IF($A29="","",IF(INDEX(BOM!$K$2:$K$110,MATCH(28,BOM!$O$2:$O$110,0))="","",HYPERLINK(INDEX(BOM!$K$2:$K$110,MATCH(28,BOM!$O$2:$O$110,0)),"open on amazon.ca"))) -> open on amazon.ca | G29: =IF($A29="","",HYPERLINK(INDEX(BOM!$L$2:$L$110,MATCH(28,BOM!$O$2:$O$110,0)),"search")) -> search
A30: =IF(ISNA(MATCH(29,BOM!$O$2:$O$110,0)),"",29) -> 29 | B30: =IF($A30="","",INDEX(BOM!$B$2:$B$110,MATCH(29,BOM!$O$2:$O$110,0))) -> EC11 rotary encoder with push switch + knob, 10 pcs | C30: =IF($A30="","",INDEX(BOM!$G$2:$G$110,MATCH(29,BOM!$O$2:$O$110,0))) -> 1 | D30: =IF($A30="","",INDEX(BOM!$H$2:$H$110,MATCH(29,BOM!$O$2:$O$110,0))) -> 17.99 | E30: =IF($A30="","",INDEX(BOM!$I$2:$I$110,MATCH(29,BOM!$O$2:$O$110,0))) -> 17.99 | F30: =IF($A30="","",IF(INDEX(BOM!$K$2:$K$110,MATCH(29,BOM!$O$2:$O$110,0))="","",HYPERLINK(INDEX(BOM!$K$2:$K$110,MATCH(29,BOM!$O$2:$O$110,0)),"open on amazon.ca"))) -> open on amazon.ca | G30: =IF($A30="","",HYPERLINK(INDEX(BOM!$L$2:$L$110,MATCH(29,BOM!$O$2:$O$110,0)),"search")) -> search
A31: =IF(ISNA(MATCH(30,BOM!$O$2:$O$110,0)),"",30) -> 30 | B31: =IF($A31="","",INDEX(BOM!$B$2:$B$110,MATCH(30,BOM!$O$2:$O$110,0))) -> B10K linear potentiometer, 16 mm, 6 mm D shaft | C31: =IF($A31="","",INDEX(BOM!$G$2:$G$110,MATCH(30,BOM!$O$2:$O$110,0))) -> 1 | D31: =IF($A31="","",INDEX(BOM!$H$2:$H$110,MATCH(30,BOM!$O$2:$O$110,0))) -> 6.95 | E31: =IF($A31="","",INDEX(BOM!$I$2:$I$110,MATCH(30,BOM!$O$2:$O$110,0))) -> 6.95 | F31: =IF($A31="","",IF(INDEX(BOM!$K$2:$K$110,MATCH(30,BOM!$O$2:$O$110,0))="","",HYPERLINK(INDEX(BOM!$K$2:$K$110,MATCH(30,BOM!$O$2:$O$110,0)),"open on amazon.ca"))) -> open on amazon.ca | G31: =IF($A31="","",HYPERLINK(INDEX(BOM!$L$2:$L$110,MATCH(30,BOM!$O$2:$O$110,0)),"search")) -> search
A32: =IF(ISNA(MATCH(31,BOM!$O$2:$O$110,0)),"",31) -> 31 | B32: =IF($A32="","",INDEX(BOM!$B$2:$B$110,MATCH(31,BOM!$O$2:$O$110,0))) -> KW11 lever micro switch, 10 pcs | C32: =IF($A32="","",INDEX(BOM!$G$2:$G$110,MATCH(31,BOM!$O$2:$O$110,0))) -> 1 | D32: =IF($A32="","",INDEX(BOM!$H$2:$H$110,MATCH(31,BOM!$O$2:$O$110,0))) -> 15.79 | E32: =IF($A32="","",INDEX(BOM!$I$2:$I$110,MATCH(31,BOM!$O$2:$O$110,0))) -> 15.79 | F32: =IF($A32="","",IF(INDEX(BOM!$K$2:$K$110,MATCH(31,BOM!$O$2:$O$110,0))="","",HYPERLINK(INDEX(BOM!$K$2:$K$110,MATCH(31,BOM!$O$2:$O$110,0)),"open on amazon.ca"))) -> open on amazon.ca | G32: =IF($A32="","",HYPERLINK(INDEX(BOM!$L$2:$L$110,MATCH(31,BOM!$O$2:$O$110,0)),"search")) -> search
A33: =IF(ISNA(MATCH(32,BOM!$O$2:$O$110,0)),"",32) -> 32 | B33: =IF($A33="","",INDEX(BOM!$B$2:$B$110,MATCH(32,BOM!$O$2:$O$110,0))) -> 19 mm key switch, 2 position, key removable in OFF | C33: =IF($A33="","",INDEX(BOM!$G$2:$G$110,MATCH(32,BOM!$O$2:$O$110,0))) -> 1 | D33: =IF($A33="","",INDEX(BOM!$H$2:$H$110,MATCH(32,BOM!$O$2:$O$110,0))) -> 26.11 | E33: =IF($A33="","",INDEX(BOM!$I$2:$I$110,MATCH(32,BOM!$O$2:$O$110,0))) -> 26.11 | F33: =IF($A33="","",IF(INDEX(BOM!$K$2:$K$110,MATCH(32,BOM!$O$2:$O$110,0))="","",HYPERLINK(INDEX(BOM!$K$2:$K$110,MATCH(32,BOM!$O$2:$O$110,0)),"open on amazon.ca"))) -> open on amazon.ca | G33: =IF($A33="","",HYPERLINK(INDEX(BOM!$L$2:$L$110,MATCH(32,BOM!$O$2:$O$110,0)),"search")) -> search
A34: =IF(ISNA(MATCH(33,BOM!$O$2:$O$110,0)),"",33) -> 33 | B34: =IF($A34="","",INDEX(BOM!$B$2:$B$110,MATCH(33,BOM!$O$2:$O$110,0))) -> WS2812B LED strip 5 V, 60 LED/m, 5 m, IP30 (no sleeve) | C34: =IF($A34="","",INDEX(BOM!$G$2:$G$110,MATCH(33,BOM!$O$2:$O$110,0))) -> 1 | D34: =IF($A34="","",INDEX(BOM!$H$2:$H$110,MATCH(33,BOM!$O$2:$O$110,0))) -> 25.99 | E34: =IF($A34="","",INDEX(BOM!$I$2:$I$110,MATCH(33,BOM!$O$2:$O$110,0))) -> 25.99 | F34: =IF($A34="","",IF(INDEX(BOM!$K$2:$K$110,MATCH(33,BOM!$O$2:$O$110,0))="","",HYPERLINK(INDEX(BOM!$K$2:$K$110,MATCH(33,BOM!$O$2:$O$110,0)),"open on amazon.ca"))) -> open on amazon.ca | G34: =IF($A34="","",HYPERLINK(INDEX(BOM!$L$2:$L$110,MATCH(33,BOM!$O$2:$O$110,0)),"search")) -> search
A35: =IF(ISNA(MATCH(34,BOM!$O$2:$O$110,0)),"",34) -> 34 | B35: =IF($A35="","",INDEX(BOM!$B$2:$B$110,MATCH(34,BOM!$O$2:$O$110,0))) -> WS2812D-F5 5 mm through-hole addressable RGB LEDs, ~40 pcs | C35: =IF($A35="","",INDEX(BOM!$G$2:$G$110,MATCH(34,BOM!$O$2:$O$110,0))) -> 1 | D35: =IF($A35="","",INDEX(BOM!$H$2:$H$110,MATCH(34,BOM!$O$2:$O$110,0))) -> 20 | E35: =IF($A35="","",INDEX(BOM!$I$2:$I$110,MATCH(34,BOM!$O$2:$O$110,0))) -> 20 | F35: =IF($A35="","",IF(INDEX(BOM!$K$2:$K$110,MATCH(34,BOM!$O$2:$O$110,0))="","",HYPERLINK(INDEX(BOM!$K$2:$K$110,MATCH(34,BOM!$O$2:$O$110,0)),"open on amazon.ca"))) | G35: =IF($A35="","",HYPERLINK(INDEX(BOM!$L$2:$L$110,MATCH(34,BOM!$O$2:$O$110,0)),"search")) -> search
A36: =IF(ISNA(MATCH(35,BOM!$O$2:$O$110,0)),"",35) -> 35 | B36: =IF($A36="","",INDEX(BOM!$B$2:$B$110,MATCH(35,BOM!$O$2:$O$110,0))) -> 5 mm LED holders / bezels, 50 pcs | C36: =IF($A36="","",INDEX(BOM!$G$2:$G$110,MATCH(35,BOM!$O$2:$O$110,0))) -> 1 | D36: =IF($A36="","",INDEX(BOM!$H$2:$H$110,MATCH(35,BOM!$O$2:$O$110,0))) -> 9.19 | E36: =IF($A36="","",INDEX(BOM!$I$2:$I$110,MATCH(35,BOM!$O$2:$O$110,0))) -> 9.19 | F36: =IF($A36="","",IF(INDEX(BOM!$K$2:$K$110,MATCH(35,BOM!$O$2:$O$110,0))="","",HYPERLINK(INDEX(BOM!$K$2:$K$110,MATCH(35,BOM!$O$2:$O$110,0)),"open on amazon.ca"))) -> open on amazon.ca | G36: =IF($A36="","",HYPERLINK(INDEX(BOM!$L$2:$L$110,MATCH(35,BOM!$O$2:$O$110,0)),"search")) -> search
A37: =IF(ISNA(MATCH(36,BOM!$O$2:$O$110,0)),"",36) -> 36 | B37: =IF($A37="","",INDEX(BOM!$B$2:$B$110,MATCH(36,BOM!$O$2:$O$110,0))) -> Mean Well LRS-50-5 (5 V 10 A) power supply | C37: =IF($A37="","",INDEX(BOM!$G$2:$G$110,MATCH(36,BOM!$O$2:$O$110,0))) -> 1 | D37: =IF($A37="","",INDEX(BOM!$H$2:$H$110,MATCH(36,BOM!$O$2:$O$110,0))) -> 31.75 | E37: =IF($A37="","",INDEX(BOM!$I$2:$I$110,MATCH(36,BOM!$O$2:$O$110,0))) -> 31.75 | F37: =IF($A37="","",IF(INDEX(BOM!$K$2:$K$110,MATCH(36,BOM!$O$2:$O$110,0))="","",HYPERLINK(INDEX(BOM!$K$2:$K$110,MATCH(36,BOM!$O$2:$O$110,0)),"open on amazon.ca"))) -> open on amazon.ca | G37: =IF($A37="","",HYPERLINK(INDEX(BOM!$L$2:$L$110,MATCH(36,BOM!$O$2:$O$110,0)),"search")) -> search
A38: =IF(ISNA(MATCH(37,BOM!$O$2:$O$110,0)),"",37) -> 37 | B38: =IF($A38="","",INDEX(BOM!$B$2:$B$110,MATCH(37,BOM!$O$2:$O$110,0))) -> Inline 5x20 mm fuse holders + fast-blow fuse kit | C38: =IF($A38="","",INDEX(BOM!$G$2:$G$110,MATCH(37,BOM!$O$2:$O$110,0))) -> 1 | D38: =IF($A38="","",INDEX(BOM!$H$2:$H$110,MATCH(37,BOM!$O$2:$O$110,0))) -> 14.99 | E38: =IF($A38="","",INDEX(BOM!$I$2:$I$110,MATCH(37,BOM!$O$2:$O$110,0))) -> 14.99 | F38: =IF($A38="","",IF(INDEX(BOM!$K$2:$K$110,MATCH(37,BOM!$O$2:$O$110,0))="","",HYPERLINK(INDEX(BOM!$K$2:$K$110,MATCH(37,BOM!$O$2:$O$110,0)),"open on amazon.ca"))) -> open on amazon.ca | G38: =IF($A38="","",HYPERLINK(INDEX(BOM!$L$2:$L$110,MATCH(37,BOM!$O$2:$O$110,0)),"search")) -> search
A39: =IF(ISNA(MATCH(38,BOM!$O$2:$O$110,0)),"",38) -> 38 | B39: =IF($A39="","",INDEX(BOM!$B$2:$B$110,MATCH(38,BOM!$O$2:$O$110,0))) -> 16 AWG red/black 2-conductor wire, 15 m (50 ft) | C39: =IF($A39="","",INDEX(BOM!$G$2:$G$110,MATCH(38,BOM!$O$2:$O$110,0))) -> 1 | D39: =IF($A39="","",INDEX(BOM!$H$2:$H$110,MATCH(38,BOM!$O$2:$O$110,0))) -> 16.99 | E39: =IF($A39="","",INDEX(BOM!$I$2:$I$110,MATCH(38,BOM!$O$2:$O$110,0))) -> 16.99 | F39: =IF($A39="","",IF(INDEX(BOM!$K$2:$K$110,MATCH(38,BOM!$O$2:$O$110,0))="","",HYPERLINK(INDEX(BOM!$K$2:$K$110,MATCH(38,BOM!$O$2:$O$110,0)),"open on amazon.ca"))) -> open on amazon.ca | G39: =IF($A39="","",HYPERLINK(INDEX(BOM!$L$2:$L$110,MATCH(38,BOM!$O$2:$O$110,0)),"search")) -> search
A40: =IF(ISNA(MATCH(39,BOM!$O$2:$O$110,0)),"",39) -> 39 | B40: =IF($A40="","",INDEX(BOM!$B$2:$B$110,MATCH(39,BOM!$O$2:$O$110,0))) -> 18 AWG red/black silicone wire, 7.6 m (25 ft) | C40: =IF($A40="","",INDEX(BOM!$G$2:$G$110,MATCH(39,BOM!$O$2:$O$110,0))) -> 2 | D40: =IF($A40="","",INDEX(BOM!$H$2:$H$110,MATCH(39,BOM!$O$2:$O$110,0))) -> 19.82 | E40: =IF($A40="","",INDEX(BOM!$I$2:$I$110,MATCH(39,BOM!$O$2:$O$110,0))) -> 39.64 | F40: =IF($A40="","",IF(INDEX(BOM!$K$2:$K$110,MATCH(39,BOM!$O$2:$O$110,0))="","",HYPERLINK(INDEX(BOM!$K$2:$K$110,MATCH(39,BOM!$O$2:$O$110,0)),"open on amazon.ca"))) -> open on amazon.ca | G40: =IF($A40="","",HYPERLINK(INDEX(BOM!$L$2:$L$110,MATCH(39,BOM!$O$2:$O$110,0)),"search")) -> search
...

Sheet Notes
A1: The Filament Falcon - BOM notes (built 2026-10-09, Atlantic time ADT/AST; location Fredericton, NB)
A2: Sources: filament-falcon/docs/SPEC.md; ff-fw/docs/electronics/README.md; filament-falcon (branch pod-single, frame v0.3 single pod actuator): frame/BOM.md v0.3, frame/cut_list.md, docs/mechanical/README.md, switch_bom.md, displays.md.
A3: Filament method: python trimesh volume V and surface area A of every 3MF (panels: single-material body = black, letter inserts = white; printed parts x quantities from docs/mechanical/README.md). Printed volume = shell + infill x (V - shell), shell = min(V, A x 1.2 mm) (3 perimeters x 0.4 mm, also used as top/bottom skin proxy); infill 25 % (monitor standoffs 50 %, harness hub 45 %). PETG 1.27 g/cm3, +15 % for purge/brim/failed prints.
A4: Filament result: black 3601 cm3 -> 5.26 kg (buy 6 x 1 kg); white 44 cm3 -> 0.06 kg (buy 1 x 1 kg). Red/grey parts (guard lids, throttle grip, gear arm, adapter plates) are counted in black - print them in red/grey if you have it. PLA would need ~2 % less mass, but PETG is required for the harness hub and recommended everywhere.
A5: Prices: "Verified amazon.ca price" = read from the amazon.ca product page on 2026-10-08 (buy-box price, CAD, before tax). Kent prices were read from kent.ca on 2026-10-09 with the Fredericton store selected (Fredericton South, 809 Bishop Dr, and Fredericton North, 25 Two Nations Crossing showed identical prices); they can change, check before buying. Local metal-supplier rows have Google search links for Fredericton NB. Rows marked Estimate/placeholder are NOT verified prices.
A6: Motion system (v0.3, branch pod-single): 2 cradle actuators 10"/1500 N (~364 mm retracted, self-locking); ONE pod actuator 12"/1500 N self-locking (420 mm retracted, left casing) driving both pod cheeks through a 2x2x1/8" steel torque tube; 2 gas struts ~1050 N with M8 eye ends, sized so the pod is lift-biased (actuator or clevis-pin failure sends it UP, never down); 25 mm shafts, UCP205/UCF205/SHF25; spring pawls + latch plates + Bowden release; steel hard stops; key, E-stop, 20 A fuse, hold-to-run DPDT, relays as 2 H-bridges, one pod limit set (left cheek), roller limit switches, safety edge. Check actuator retracted length and self-locking before ordering.
A7: SAFETY: the B0B3J1GCVQ buckles are plastic luggage buckles (~50 kg quoted break load, not safety-rated). Positioning harness only for a slow reclining seat. A rated metal-buckle 4-point harness is listed as an ALTERNATIVE row (excluded from totals; switch if you prefer).
A8: Displays: GPU DP1 -> C275B, HDMI -> C275W (HDMI/VGA only), DP2 -> DP-to-DVI-D -> TD2220 (VGA/DVI only), USB-A -> USB-B for touch. GPU USB-C is spare (4th display max).
A9: Owned items: PC, both Sceptres, TD2220, 3 HY300, 2 joysticks have Have it = TRUE. Buttons/switches/LEDs you may own are FALSE - tick them.
